<?xml version="1.0" ?>
<sdf version="1.9">

  <model name="tracked_v2">
    <static>false</static>
    <pose>0 0 0 0 0 0</pose>

    <link name="chassis_link">
      <pose>-0.1 0 0.26 0 0 0</pose>

      <inertial>
          <mass>100.0</mass>
          <inertia>
          <ixx>1.81</ixx> <iyy>5.81</iyy> <izz>6.67</izz>
          <ixy>0.0</ixy> <ixz>0.0</ixz> <iyz>0.0</iyz>
          </inertia>
      </inertial>

      <collision name="chassis_collision">
          <geometry>
          <box><size>0.8 0.4 0.24</size></box>
          </geometry>
      </collision>

      <visual name="chassis_visual">
          <geometry>
          <box><size>0.8 0.4 0.24</size></box>
          </geometry>
          <material>
          <ambient>0.3 0.4 0.9 1</ambient>
          <diffuse>0.3 0.4 0.9 1</diffuse>
          </material>
      </visual>

      <sensor name="imu_sensor" type="imu">
          <always_on>true</always_on>
          <update_rate>100</update_rate>
          <visualize>false</visualize>
          <topic>imu</topic>
          <pose>0.1 0 0 0 0 0</pose>

      </sensor>

      <!-- <sensor name="imu_sensor" type="imu">
        <always_on>true</always_on>
        <update_rate>100</update_rate>
        <visualize>false</visualize>
        <topic>imu</topic>
        <pose>0.1 0 0 0 0 0</pose>

        <imu>
          <angular_velocity>
            <x>
              <noise type="gaussian">
                <mean>0.0</mean>
                <stddev>0.005</stddev>
                <bias_mean>0.0</bias_mean>
                <bias_stddev>0.0005</bias_stddev>
              </noise>
            </x>
            <y>
              <noise type="gaussian">
                <mean>0.0</mean>
                <stddev>0.005</stddev>
                <bias_mean>0.0</bias_mean>
                <bias_stddev>0.0005</bias_stddev>
              </noise>
            </y>
            <z>
              <noise type="gaussian">
                <mean>0.0</mean>
                <stddev>0.005</stddev>
                <bias_mean>0.0</bias_mean>
                <bias_stddev>0.0005</bias_stddev>
              </noise>
            </z>
          </angular_velocity>

          <linear_acceleration>
            <x>
              <noise type="gaussian">
                <mean>0.0</mean>
                <stddev>0.1</stddev>
                <bias_mean>0.0</bias_mean>
                <bias_stddev>0.01</bias_stddev>
              </noise>
            </x>
            <y>
              <noise type="gaussian">
                <mean>0.0</mean>
                <stddev>0.1</stddev>
                <bias_mean>0.0</bias_mean>
                <bias_stddev>0.01</bias_stddev>
              </noise>
            </y>
            <z>
              <noise type="gaussian">
                <mean>0.0</mean>
                <stddev>0.1</stddev>
                <bias_mean>0.0</bias_mean>
                <bias_stddev>0.01</bias_stddev>
              </noise>
            </z>
          </linear_acceleration>
        </imu>
      </sensor> -->

      <sensor name="navsat_sensor" type="navsat">
        <always_on>true</always_on>
        <update_rate>10.0</update_rate>
        <topic>navsat</topic>
        <visualize>false</visualize>
          <pose>0.1 0 0 0 0 0</pose>
      </sensor>

      <sensor name="magnetometer_sensor" type="magnetometer">
        <always_on>true</always_on>
        <update_rate>100.0</update_rate>
        <topic>magnetometer</topic> 
          <pose>0.1 0 0 0 0 0</pose>

      </sensor>

    </link>


    <link name="wheel_R1_link">
        <pose>0.42 -0.285 0.1 1.5708 0 0</pose>

      <visual name="wheel_R1_visual">
        <geometry>
          <!-- <mesh>
            <uri>geometry/wheel_v2.dae</uri>
            <scale>1 1 1</scale> 
          </mesh> -->
          <cylinder>
            <radius>0.1</radius>
            <length>0.15</length>
          </cylinder>
        </geometry>
        <material>
          <ambient>0.5 0.5 0.5 1</ambient>
          <diffuse>0.5 0.5 0.5 1</diffuse>
          <specular>0.1 0.1 0.1 1</specular>
        </material>
      </visual>

      <collision name="wheel_R1_collision">
        <!-- <geometry>
          <mesh>
            <uri>geometry/wheel_v3.dae</uri>
          </mesh>
        </geometry> -->
        <geometry>
          <cylinder>
            <radius>0.1</radius>
            <length>0.15</length>
          </cylinder>
        </geometry>

        <surface>
          <friction>
            <ode>
              <mu>1.2</mu>
              <mu2>0.7</mu2>
              <fdir1>1 0 0</fdir1>
              <slip1>0.0</slip1>
              <slip2>0.001</slip2>
            </ode>
          </friction>
          <contact>
            <ode>
              <soft_cfm>0.002</soft_cfm>
              <soft_erp>0.002</soft_erp>
              <kp>1000</kp>
              <kd>500</kd>
              <!-- <soft_cfm>0.001</soft_cfm>
              <soft_erp>0.0099</soft_erp>
              <kp>1000</kp>
              <kd>100</kd> -->
            </ode>
          </contact>
        </surface>
      </collision>

      <inertial>
        <mass>5.0</mass>
        <inertia>
          <ixx>0.025</ixx>
          <iyy>0.025</iyy>
          <izz>0.031</izz>
          <ixy>0</ixy>
          <ixz>0</ixz>
          <iyz>0</iyz>
        </inertia>
      </inertial>
    </link>

    <joint name="wheel_R1_joint" type="revolute">
      <parent>chassis_link</parent>
      <child>wheel_R1_link</child>

      <pose>0 0 0 0 0 0</pose>

      <axis>
        <xyz>0 0 -1</xyz>

        <limit>
          <lower>-1.79769e+308</lower>
          <upper>1.79769e+308</upper>
          <effort>10000.0</effort>
          <velocity>10000.0</velocity>
        </limit>

        <dynamics>
          <damping>0.1</damping> 
          <friction>0.01</friction> 
        </dynamics>
      </axis>

      <physics>
        <provide_feedback>true</provide_feedback>
      </physics>

    </joint>


    <link name="wheel_R2_link">
        <pose>0.21 -0.285 0.1 1.5708 0 0</pose>

      <visual name="wheel_R2_visual">
        <geometry>
          <!-- <mesh>
            <uri>geometry/wheel_v2.dae</uri>
            <scale>1 1 1</scale> 
          </mesh> -->
          <cylinder>
            <radius>0.1</radius>
            <length>0.15</length>
          </cylinder>
        </geometry>
        <material>
          <ambient>0.5 0.5 0.5 1</ambient>
          <diffuse>0.5 0.5 0.5 1</diffuse>
          <specular>0.1 0.1 0.1 1</specular>
        </material>
      </visual>

      <collision name="wheel_R2_collision">
        <!-- <geometry>
          <mesh>
            <uri>geometry/wheel_v3.dae</uri>
          </mesh>
        </geometry> -->
        <geometry>
          <cylinder>
            <radius>0.1</radius>
            <length>0.15</length>
          </cylinder>
        </geometry>

        <surface>
          <friction>
            <ode>
              <mu>1.2</mu>
              <mu2>0.7</mu2>
              <fdir1>1 0 0</fdir1>
              <slip1>0.0</slip1>
              <slip2>0.001</slip2>
            </ode>
          </friction>
          <contact>
            <ode>
              <soft_cfm>0.002</soft_cfm>
              <soft_erp>0.002</soft_erp>
              <kp>1000</kp>
              <kd>500</kd>
              <!-- <soft_cfm>0.001</soft_cfm>
              <soft_erp>0.0099</soft_erp>
              <kp>1000</kp>
              <kd>100</kd> -->
            </ode>
          </contact>
        </surface>
      </collision>

      <inertial>
        <mass>5.0</mass>
        <inertia>
          <ixx>0.025</ixx>
          <iyy>0.025</iyy>
          <izz>0.031</izz>
          <ixy>0</ixy>
          <ixz>0</ixz>
          <iyz>0</iyz>
        </inertia>
      </inertial>
    </link>

    <joint name="wheel_R2_joint" type="revolute">
      <parent>chassis_link</parent>
      <child>wheel_R2_link</child>

      <pose>0 0 0 0 0 0</pose>

      <axis>
        <xyz>0 0 -1</xyz>

        <limit>
          <lower>-1.79769e+308</lower>
          <upper>1.79769e+308</upper>
          <effort>10000.0</effort>
          <velocity>10000.0</velocity>
        </limit>

        <dynamics>
          <damping>0.1</damping> 
          <friction>0.01</friction> 
        </dynamics>
      </axis>

      <physics>
        <provide_feedback>true</provide_feedback>
      </physics>

    </joint>


    <link name="wheel_R3_link">
        <pose>0 -0.285 0.1 1.5708 0 0</pose>

      <visual name="wheel_R3_visual">
        <geometry>
          <!-- <mesh>
            <uri>geometry/wheel_v2.dae</uri>
            <scale>1 1 1</scale> 
          </mesh> -->
          <cylinder>
            <radius>0.1</radius>
            <length>0.15</length>
          </cylinder>
        </geometry>
        <material>
          <ambient>0.5 0.5 0.5 1</ambient>
          <diffuse>0.5 0.5 0.5 1</diffuse>
          <specular>0.1 0.1 0.1 1</specular>
        </material>
      </visual>

      <collision name="wheel_R3_collision">
        <!-- <geometry>
          <mesh>
            <uri>geometry/wheel_v3.dae</uri>
          </mesh>
        </geometry> -->
        <geometry>
          <cylinder>
            <radius>0.1</radius>
            <length>0.15</length>
          </cylinder>
        </geometry>

        <surface>
          <friction>
            <ode>
              <mu>1.2</mu>
              <mu2>0.7</mu2>
              <fdir1>1 0 0</fdir1>
              <slip1>0.0</slip1>
              <slip2>0.001</slip2>
            </ode>
          </friction>
          <contact>
            <ode>
              <soft_cfm>0.002</soft_cfm>
              <soft_erp>0.002</soft_erp>
              <kp>1000</kp>
              <kd>500</kd>
              <!-- <soft_cfm>0.001</soft_cfm>
              <soft_erp>0.0099</soft_erp>
              <kp>1000</kp>
              <kd>100</kd> -->
            </ode>
          </contact>
        </surface>
      </collision>

      <inertial>
        <mass>5.0</mass>
        <inertia>
          <ixx>0.025</ixx>
          <iyy>0.025</iyy>
          <izz>0.031</izz>
          <ixy>0</ixy>
          <ixz>0</ixz>
          <iyz>0</iyz>
        </inertia>
      </inertial>
    </link>

    <joint name="wheel_R3_joint" type="revolute">
      <parent>chassis_link</parent>
      <child>wheel_R3_link</child>

      <pose>0 0 0 0 0 0</pose>

      <axis>
        <xyz>0 0 -1</xyz>

        <limit>
          <lower>-1.79769e+308</lower>
          <upper>1.79769e+308</upper>
          <effort>10000.0</effort>
          <velocity>10000.0</velocity>
        </limit>

        <dynamics>
          <damping>0.1</damping> 
          <friction>0.01</friction> 
        </dynamics>
      </axis>

      <physics>
        <provide_feedback>true</provide_feedback>
      </physics>

    </joint>


    <link name="wheel_R4_link">
        <pose>-0.21 -0.285 0.1 1.5708 0 0</pose>

      <visual name="wheel_R4_visual">
        <geometry>
          <!-- <mesh>
            <uri>geometry/wheel_v2.dae</uri>
            <scale>1 1 1</scale> 
          </mesh> -->
          <cylinder>
            <radius>0.1</radius>
            <length>0.15</length>
          </cylinder>
        </geometry>
        <material>
          <ambient>0.5 0.5 0.5 1</ambient>
          <diffuse>0.5 0.5 0.5 1</diffuse>
          <specular>0.1 0.1 0.1 1</specular>
        </material>
      </visual>

      <collision name="wheel_R4_collision">
        <!-- <geometry>
          <mesh>
            <uri>geometry/wheel_v3.dae</uri>
          </mesh>
        </geometry> -->
        <geometry>
          <cylinder>
            <radius>0.1</radius>
            <length>0.15</length>
          </cylinder>
        </geometry>

        <surface>
          <friction>
            <ode>
              <mu>1.2</mu>
              <mu2>0.7</mu2>
              <fdir1>1 0 0</fdir1>
              <slip1>0.0</slip1>
              <slip2>0.001</slip2>
            </ode>
          </friction>
          <contact>
            <ode>
              <soft_cfm>0.002</soft_cfm>
              <soft_erp>0.002</soft_erp>
              <kp>1000</kp>
              <kd>500</kd>
              <!-- <soft_cfm>0.001</soft_cfm>
              <soft_erp>0.0099</soft_erp>
              <kp>1000</kp>
              <kd>100</kd> -->
            </ode>
          </contact>
        </surface>
      </collision>

      <inertial>
        <mass>5.0</mass>
        <inertia>
          <ixx>0.025</ixx>
          <iyy>0.025</iyy>
          <izz>0.031</izz>
          <ixy>0</ixy>
          <ixz>0</ixz>
          <iyz>0</iyz>
        </inertia>
      </inertial>
    </link>

    <joint name="wheel_R4_joint" type="revolute">
      <parent>chassis_link</parent>
      <child>wheel_R4_link</child>

      <pose>0 0 0 0 0 0</pose>

      <axis>
        <xyz>0 0 -1</xyz>

        <limit>
          <lower>-1.79769e+308</lower>
          <upper>1.79769e+308</upper>
          <effort>10000.0</effort>
          <velocity>10000.0</velocity>
        </limit>

        <dynamics>
          <damping>0.1</damping> 
          <friction>0.01</friction> 
        </dynamics>
      </axis>

      <physics>
        <provide_feedback>true</provide_feedback>
      </physics>

    </joint>


    <link name="wheel_R5_link">
        <pose>-0.42 -0.285 0.1 1.5708 0 0</pose>

      <visual name="wheel_R5_visual">
        <geometry>
          <!-- <mesh>
            <uri>geometry/wheel_v2.dae</uri>
            <scale>1 1 1</scale> 
          </mesh> -->
          <cylinder>
            <radius>0.1</radius>
            <length>0.15</length>
          </cylinder>
        </geometry>
        <material>
          <ambient>0.5 0.5 0.5 1</ambient>
          <diffuse>0.5 0.5 0.5 1</diffuse>
          <specular>0.1 0.1 0.1 1</specular>
        </material>
      </visual>

      <collision name="wheel_R5_collision">
        <!-- <geometry>
          <mesh>
            <uri>geometry/wheel_v3.dae</uri>
          </mesh>
        </geometry> -->
        <geometry>
          <cylinder>
            <radius>0.1</radius>
            <length>0.15</length>
          </cylinder>
        </geometry>

        <surface>
          <friction>
            <ode>
              <mu>1.2</mu>
              <mu2>0.7</mu2>
              <fdir1>1 0 0</fdir1>
              <slip1>0.0</slip1>
              <slip2>0.001</slip2>
            </ode>
          </friction>
          <contact>
            <ode>
              <soft_cfm>0.002</soft_cfm>
              <soft_erp>0.002</soft_erp>
              <kp>1000</kp>
              <kd>500</kd>
              <!-- <soft_cfm>0.001</soft_cfm>
              <soft_erp>0.0099</soft_erp>
              <kp>1000</kp>
              <kd>100</kd> -->
            </ode>
          </contact>
        </surface>
      </collision>

      <inertial>
        <mass>5.0</mass>
        <inertia>
          <ixx>0.025</ixx>
          <iyy>0.025</iyy>
          <izz>0.031</izz>
          <ixy>0</ixy>
          <ixz>0</ixz>
          <iyz>0</iyz>
        </inertia>
      </inertial>
    </link>

    <joint name="wheel_R5_joint" type="revolute">
      <parent>chassis_link</parent>
      <child>wheel_R5_link</child>

      <pose>0 0 0 0 0 0</pose>

      <axis>
        <xyz>0 0 -1</xyz>

        <limit>
          <lower>-1.79769e+308</lower>
          <upper>1.79769e+308</upper>
          <effort>10000.0</effort>
          <velocity>10000.0</velocity>
        </limit>

        <dynamics>
          <damping>0.1</damping> 
          <friction>0.01</friction> 
        </dynamics>
      </axis>

      <physics>
        <provide_feedback>true</provide_feedback>
      </physics>

    </joint>


    <!-- <link name="guide_R_link">
      <pose>0 -0.38 0.17 0 0 0</pose>

      <visual name="guide_R_visual">
        <geometry>
          <box>
            <size>0.84 0.02 0.03</size>
          </box>
        </geometry>
        <material>
          <ambient>0 0 0 1</ambient>
          <diffuse>0 0 0 1</diffuse>
        </material>
      </visual>

      <collision name="guide_R_collision">
        <geometry>
          <box>
            <size>0.84 0.02 0.03</size>
          </box>
        </geometry>
      </collision>

      <collision name="R1_collision">
        <pose>0.42 0.05 0 1.5708 0 0</pose>
        <geometry>
        
          <cylinder>
            <radius>0.008</radius>
            <length>0.1</length>
          </cylinder>
        </geometry>

        <surface>
          <friction>
            <ode>
              <mu>0.1</mu>
              <mu2>0.1</mu2>
            </ode>
          </friction>
          <contact>
            <ode>
              <soft_cfm>0.002</soft_cfm>
              <soft_erp>0.002</soft_erp>
              <kp>1000</kp>
              <kd>500</kd>
            </ode>
          </contact>
        </surface>
      </collision>

      <collision name="R2_collision">
        <pose>0.21 0.05 0 1.5708 0 0</pose>
        <geometry>
        
          <cylinder>
            <radius>0.008</radius>
            <length>0.1</length>
          </cylinder>
        </geometry>

        <surface>
          <friction>
            <ode>
              <mu>0.1</mu>
              <mu2>0.1</mu2>
            </ode>
          </friction>
          <contact>
            <ode>
              <soft_cfm>0.002</soft_cfm>
              <soft_erp>0.002</soft_erp>
              <kp>1000</kp>
              <kd>500</kd>
            </ode>
          </contact>
        </surface>
      </collision>

      <collision name="R3_collision">
        <pose>0 0.05 0 1.5708 0 0</pose>
        <geometry>
        
          <cylinder>
            <radius>0.008</radius>
            <length>0.1</length>
          </cylinder>
        </geometry>

        <surface>
          <friction>
            <ode>
              <mu>0.1</mu>
              <mu2>0.1</mu2>
            </ode>
          </friction>
          <contact>
            <ode>
              <soft_cfm>0.002</soft_cfm>
              <soft_erp>0.002</soft_erp>
              <kp>1000</kp>
              <kd>500</kd>
            </ode>
          </contact>
        </surface>
      </collision>

      <collision name="R4_collision">
        <pose>-0.21 0.05 0 1.5708 0 0</pose>
        <geometry>
        
          <cylinder>
            <radius>0.008</radius>
            <length>0.1</length>
          </cylinder>
        </geometry>

        <surface>
          <friction>
            <ode>
              <mu>0.1</mu>
              <mu2>0.1</mu2>
            </ode>
          </friction>
          <contact>
            <ode>
              <soft_cfm>0.002</soft_cfm>
              <soft_erp>0.002</soft_erp>
              <kp>1000</kp>
              <kd>500</kd>
            </ode>
          </contact>
        </surface>
      </collision>

      <collision name="R5_collision">
        <pose>-0.42 0.05 0 1.5708 0 0</pose>
        <geometry>
        
          <cylinder>
            <radius>0.008</radius>
            <length>0.1</length>
          </cylinder>
        </geometry>

        <surface>
          <friction>
            <ode>
              <mu>0.1</mu>
              <mu2>0.1</mu2>
            </ode>
          </friction>
          <contact>
            <ode>
              <soft_cfm>0.002</soft_cfm>
              <soft_erp>0.002</soft_erp>
              <kp>1000</kp>
              <kd>500</kd>
            </ode>
          </contact>
        </surface>
      </collision>

      <inertial>
        <mass>1.0</mass>
        <inertia>
          <ixx>0.01</ixx> <iyy>0.01</iyy> <izz>0.01</izz>
          <ixy>0.0</ixy> <ixz>0.0</ixz> <iyz>0.0</iyz>
        </inertia>
      </inertial>
    </link>

    <joint name="guide_R_joint" type="revolute">
      <parent>wheel_R5_link</parent>
      <child>guide_R_link</child>

      <pose>0 0 0 0 0 0</pose>

      <axis>
        <xyz>0 -1 0</xyz>

        <limit>
          <lower>-1000000</lower>
          <upper>1000000</upper> 
        </limit>

        <dynamics>
          <damping>0.1</damping> 
          <friction>0.0</friction> 
        </dynamics>

      </axis>

    </joint> -->

    <link name="wheel_L1_link">
        <pose>0.42 0.285 0.1 1.5708 0 0</pose>

      <visual name="wheel_L1_visual">
        <geometry>
          <!-- <mesh>
            <uri>geometry/wheel_v2.dae</uri>
            <scale>1 1 1</scale> 
          </mesh> -->
          <cylinder>
            <radius>0.1</radius>
            <length>0.15</length>
          </cylinder>
        </geometry>
        <material>
          <ambient>0.5 0.5 0.5 1</ambient>
          <diffuse>0.5 0.5 0.5 1</diffuse>
          <specular>0.1 0.1 0.1 1</specular>
        </material>
      </visual>

      <collision name="wheel_L1_collision">
        <!-- <geometry>
          <mesh>
            <uri>geometry/wheel_v3.dae</uri>
          </mesh>
        </geometry> -->
        <geometry>
          <cylinder>
            <radius>0.1</radius>
            <length>0.15</length>
          </cylinder>
        </geometry>

        <surface>
          <friction>
            <ode>
              <mu>1.2</mu>
              <mu2>0.7</mu2>
              <fdir1>1 0 0</fdir1>
              <slip1>0.0</slip1>
              <slip2>0.001</slip2>
            </ode>
          </friction>
          <contact>
            <ode>
              <soft_cfm>0.002</soft_cfm>
              <soft_erp>0.002</soft_erp>
              <kp>1000</kp>
              <kd>500</kd>
              <!-- <soft_cfm>0.001</soft_cfm>
              <soft_erp>0.0099</soft_erp>
              <kp>1000</kp>
              <kd>100</kd> -->
            </ode>
          </contact>
        </surface>
      </collision>

      <inertial>
        <mass>5.0</mass>
        <inertia>
          <ixx>0.025</ixx>
          <iyy>0.025</iyy>
          <izz>0.031</izz>
          <ixy>0</ixy>
          <ixz>0</ixz>
          <iyz>0</iyz>
        </inertia>
      </inertial>
    </link>

    <joint name="wheel_L1_joint" type="revolute">
      <parent>chassis_link</parent>
      <child>wheel_L1_link</child>

      <pose>0 0 0 0 0 0</pose>

      <axis>
        <xyz>0 0 -1</xyz>

        <limit>
          <lower>-1.79769e+308</lower>
          <upper>1.79769e+308</upper>
          <effort>10000.0</effort>
          <velocity>10000.0</velocity>
        </limit>

        <dynamics>
          <damping>0.1</damping> 
          <friction>0.01</friction> 
        </dynamics>
      </axis>

      <physics>
        <provide_feedback>true</provide_feedback>
      </physics>

    </joint>


    <link name="wheel_L2_link">
        <pose>0.21 0.285 0.1 1.5708 0 0</pose>

      <visual name="wheel_L2_visual">
        <geometry>
          <!-- <mesh>
            <uri>geometry/wheel_v2.dae</uri>
            <scale>1 1 1</scale> 
          </mesh> -->
          <cylinder>
            <radius>0.1</radius>
            <length>0.15</length>
          </cylinder>
        </geometry>
        <material>
          <ambient>0.5 0.5 0.5 1</ambient>
          <diffuse>0.5 0.5 0.5 1</diffuse>
          <specular>0.1 0.1 0.1 1</specular>
        </material>
      </visual>

      <collision name="wheel_L2_collision">
        <!-- <geometry>
          <mesh>
            <uri>geometry/wheel_v3.dae</uri>
          </mesh>
        </geometry> -->
        <geometry>
          <cylinder>
            <radius>0.1</radius>
            <length>0.15</length>
          </cylinder>
        </geometry>

        <surface>
          <friction>
            <ode>
              <mu>1.2</mu>
              <mu2>0.7</mu2>
              <fdir1>1 0 0</fdir1>
              <slip1>0.0</slip1>
              <slip2>0.001</slip2>
            </ode>
          </friction>
          <contact>
            <ode>
              <soft_cfm>0.002</soft_cfm>
              <soft_erp>0.002</soft_erp>
              <kp>1000</kp>
              <kd>500</kd>
              <!-- <soft_cfm>0.001</soft_cfm>
              <soft_erp>0.0099</soft_erp>
              <kp>1000</kp>
              <kd>100</kd> -->
            </ode>
          </contact>
        </surface>
      </collision>

      <inertial>
        <mass>5.0</mass>
        <inertia>
          <ixx>0.025</ixx>
          <iyy>0.025</iyy>
          <izz>0.031</izz>
          <ixy>0</ixy>
          <ixz>0</ixz>
          <iyz>0</iyz>
        </inertia>
      </inertial>
    </link>

    <joint name="wheel_L2_joint" type="revolute">
      <parent>chassis_link</parent>
      <child>wheel_L2_link</child>

      <pose>0 0 0 0 0 0</pose>

      <axis>
        <xyz>0 0 -1</xyz>

        <limit>
          <lower>-1.79769e+308</lower>
          <upper>1.79769e+308</upper>
          <effort>10000.0</effort>
          <velocity>10000.0</velocity>
        </limit>

        <dynamics>
          <damping>0.1</damping> 
          <friction>0.01</friction> 
        </dynamics>
      </axis>

      <physics>
        <provide_feedback>true</provide_feedback>
      </physics>

    </joint>


    <link name="wheel_L3_link">
        <pose>0 0.285 0.1 1.5708 0 0</pose>

      <visual name="wheel_L3_visual">
        <geometry>
          <!-- <mesh>
            <uri>geometry/wheel_v2.dae</uri>
            <scale>1 1 1</scale> 
          </mesh> -->
          <cylinder>
            <radius>0.1</radius>
            <length>0.15</length>
          </cylinder>
        </geometry>
        <material>
          <ambient>0.5 0.5 0.5 1</ambient>
          <diffuse>0.5 0.5 0.5 1</diffuse>
          <specular>0.1 0.1 0.1 1</specular>
        </material>
      </visual>

      <collision name="wheel_L3_collision">
        <!-- <geometry>
          <mesh>
            <uri>geometry/wheel_v3.dae</uri>
          </mesh>
        </geometry> -->
        <geometry>
          <cylinder>
            <radius>0.1</radius>
            <length>0.15</length>
          </cylinder>
        </geometry>

        <surface>
          <friction>
            <ode>
              <mu>1.2</mu>
              <mu2>0.7</mu2>
              <fdir1>1 0 0</fdir1>
              <slip1>0.0</slip1>
              <slip2>0.001</slip2>
            </ode>
          </friction>
          <contact>
            <ode>
              <soft_cfm>0.002</soft_cfm>
              <soft_erp>0.002</soft_erp>
              <kp>1000</kp>
              <kd>500</kd>
              <!-- <soft_cfm>0.001</soft_cfm>
              <soft_erp>0.0099</soft_erp>
              <kp>1000</kp>
              <kd>100</kd> -->
            </ode>
          </contact>
        </surface>
      </collision>

      <inertial>
        <mass>5.0</mass>
        <inertia>
          <ixx>0.025</ixx>
          <iyy>0.025</iyy>
          <izz>0.031</izz>
          <ixy>0</ixy>
          <ixz>0</ixz>
          <iyz>0</iyz>
        </inertia>
      </inertial>
    </link>

    <joint name="wheel_L3_joint" type="revolute">
      <parent>chassis_link</parent>
      <child>wheel_L3_link</child>

      <pose>0 0 0 0 0 0</pose>

      <axis>
        <xyz>0 0 -1</xyz>

        <limit>
          <lower>-1.79769e+308</lower>
          <upper>1.79769e+308</upper>
          <effort>10000.0</effort>
          <velocity>10000.0</velocity>
        </limit>

        <dynamics>
          <damping>0.1</damping> 
          <friction>0.01</friction> 
        </dynamics>
      </axis>

      <physics>
        <provide_feedback>true</provide_feedback>
      </physics>

    </joint>


    <link name="wheel_L4_link">
        <pose>-0.21 0.285 0.1 1.5708 0 0</pose>

      <visual name="wheel_L4_visual">
        <geometry>
          <!-- <mesh>
            <uri>geometry/wheel_v3.dae</uri>
            <scale>1 1 1</scale> 
          </mesh> -->
          <cylinder>
            <radius>0.1</radius>
            <length>0.15</length>
          </cylinder>
        </geometry>
        <material>
          <ambient>0.5 0.5 0.5 1</ambient>
          <diffuse>0.5 0.5 0.5 1</diffuse>
          <specular>0.1 0.1 0.1 1</specular>
        </material>
      </visual>

      <collision name="wheel_L4_collision">
        <!-- <geometry>
          <mesh>
            <uri>geometry/wheel_v3.dae</uri>
          </mesh>
        </geometry> -->
        <geometry>
          <cylinder>
            <radius>0.1</radius>
            <length>0.15</length>
          </cylinder>
        </geometry>

        <surface>
          <friction>
            <ode>
              <mu>1.2</mu>
              <mu2>0.7</mu2>
              <fdir1>1 0 0</fdir1>
              <slip1>0.0</slip1>
              <slip2>0.001</slip2>
            </ode>
          </friction>
          <contact>
            <ode>
              <soft_cfm>0.002</soft_cfm>
              <soft_erp>0.002</soft_erp>
              <kp>1000</kp>
              <kd>500</kd>
              <!-- <soft_cfm>0.001</soft_cfm>
              <soft_erp>0.0099</soft_erp>
              <kp>1000</kp>
              <kd>100</kd> -->
            </ode>
          </contact>
        </surface>
      </collision>

      <inertial>
        <mass>5.0</mass>
        <inertia>
          <ixx>0.025</ixx>
          <iyy>0.025</iyy>
          <izz>0.031</izz>
          <ixy>0</ixy>
          <ixz>0</ixz>
          <iyz>0</iyz>
        </inertia>
      </inertial>
    </link>

    <joint name="wheel_L4_joint" type="revolute">
      <parent>chassis_link</parent>
      <child>wheel_L4_link</child>

      <pose>0 0 0 0 0 0</pose>

      <axis>
        <xyz>0 0 -1</xyz>

        <limit>
          <lower>-1.79769e+308</lower>
          <upper>1.79769e+308</upper>
          <effort>10000.0</effort>
          <velocity>10000.0</velocity>
        </limit>

        <dynamics>
          <damping>0.1</damping> 
          <friction>0.01</friction> 
        </dynamics>
      </axis>

      <physics>
        <provide_feedback>true</provide_feedback>
      </physics>

    </joint>


    <link name="wheel_L5_link">
        <pose>-0.42 0.285 0.1 1.5708 0 0</pose>

      <visual name="wheel_L5_visual">
        <geometry>
          <!-- <mesh>
            <uri>geometry/wheel_v2.dae</uri>
            <scale>1 1 1</scale> 
          </mesh> -->
          <cylinder>
            <radius>0.1</radius>
            <length>0.15</length>
          </cylinder>
        </geometry>
        <material>
          <ambient>0.5 0.5 0.5 1</ambient>
          <diffuse>0.5 0.5 0.5 1</diffuse>
          <specular>0.1 0.1 0.1 1</specular>
        </material>
      </visual>

      <collision name="wheel_L5_collision">
        <!-- <geometry>
          <mesh>
            <uri>geometry/wheel_v3.dae</uri>
          </mesh>
        </geometry> -->
        <geometry>
          <cylinder>
            <radius>0.1</radius>
            <length>0.15</length>
          </cylinder>
        </geometry>

        <surface>
          <friction>
            <ode>
              <mu>1.2</mu>
              <mu2>0.7</mu2>
              <fdir1>1 0 0</fdir1>
              <slip1>0.0</slip1>
              <slip2>0.001</slip2>
            </ode>
          </friction>
          <contact>
            <ode>
              <soft_cfm>0.002</soft_cfm>
              <soft_erp>0.002</soft_erp>
              <kp>1000</kp>
              <kd>500</kd>
              <!-- <soft_cfm>0.001</soft_cfm>
              <soft_erp>0.0099</soft_erp>
              <kp>1000</kp>
              <kd>100</kd> -->
            </ode>
          </contact>
        </surface>
      </collision>

      <inertial>
        <mass>5.0</mass>
        <inertia>
          <ixx>0.025</ixx>
          <iyy>0.025</iyy>
          <izz>0.031</izz>
          <ixy>0</ixy>
          <ixz>0</ixz>
          <iyz>0</iyz>
        </inertia>
      </inertial>
    </link>

    <joint name="wheel_L5_joint" type="revolute">
      <parent>chassis_link</parent>
      <child>wheel_L5_link</child>

      <pose>0 0 0 0 0 0</pose>

      <axis>
        <xyz>0 0 -1</xyz>

        <limit>
          <lower>-1.79769e+308</lower>
          <upper>1.79769e+308</upper>
          <effort>10000.0</effort>
          <velocity>10000.0</velocity>
        </limit>

        <dynamics>
          <damping>0.1</damping> 
          <friction>0.01</friction> 
        </dynamics>
      </axis>

      <physics>
        <provide_feedback>true</provide_feedback>
      </physics>

    </joint>


    <!-- <link name="guide_L_link">
      <pose>0 0.38 0.17 0 0 0</pose>

      <visual name="guide_L_visual">
        <geometry>
          <box>
            <size>0.84 0.02 0.03</size>
          </box>
        </geometry>
        <material>
          <ambient>0 0 0 1</ambient>
          <diffuse>0 0 0 1</diffuse>
        </material>
      </visual>

      <collision name="guide_L_collision">
        <geometry>
          <box>
            <size>0.84 0.02 0.03</size>
          </box>
        </geometry>
      </collision>

      <collision name="L1_collision">
        <pose>0.42 -0.05 0 1.5708 0 0</pose>
        <geometry>
        
          <cylinder>
            <radius>0.008</radius>
            <length>0.1</length>
          </cylinder>
        </geometry>

        <surface>
          <friction>
            <ode>
              <mu>0.1</mu>
              <mu2>0.1</mu2>
            </ode>
          </friction>
          <contact>
            <ode>
              <soft_cfm>0.002</soft_cfm>
              <soft_erp>0.002</soft_erp>
              <kp>1000</kp>
              <kd>500</kd>
            </ode>
          </contact>
        </surface>
      </collision>

      <collision name="L2_collision">
        <pose>0.21 -0.05 0 1.5708 0 0</pose>
        <geometry>
        
          <cylinder>
            <radius>0.008</radius>
            <length>0.1</length>
          </cylinder>
        </geometry>

        <surface>
          <friction>
            <ode>
              <mu>0.1</mu>
              <mu2>0.1</mu2>
            </ode>
          </friction>
          <contact>
            <ode>
              <soft_cfm>0.002</soft_cfm>
              <soft_erp>0.002</soft_erp>
              <kp>1000</kp>
              <kd>500</kd>
            </ode>
          </contact>
        </surface>
      </collision>

      <collision name="L3_collision">
        <pose>0 -0.05 0 1.5708 0 0</pose>
        <geometry>
        
          <cylinder>
            <radius>0.008</radius>
            <length>0.1</length>
          </cylinder>
        </geometry>

        <surface>
          <friction>
            <ode>
              <mu>0.1</mu>
              <mu2>0.1</mu2>
            </ode>
          </friction>
          <contact>
            <ode>
              <soft_cfm>0.002</soft_cfm>
              <soft_erp>0.002</soft_erp>
              <kp>1000</kp>
              <kd>500</kd>
            </ode>
          </contact>
        </surface>
      </collision>

      <collision name="L4_collision">
        <pose>-0.21 -0.05 0 1.5708 0 0</pose>
        <geometry>
        
          <cylinder>
            <radius>0.008</radius>
            <length>0.1</length>
          </cylinder>
        </geometry>

        <surface>
          <friction>
            <ode>
              <mu>0.1</mu>
              <mu2>0.1</mu2>
            </ode>
          </friction>
          <contact>
            <ode>
              <soft_cfm>0.002</soft_cfm>
              <soft_erp>0.002</soft_erp>
              <kp>1000</kp>
              <kd>500</kd>
            </ode>
          </contact>
        </surface>
      </collision>

      <collision name="L5_collision">
        <pose>-0.42 -0.05 0 1.5708 0 0</pose>
        <geometry>
        
          <cylinder>
            <radius>0.008</radius>
            <length>0.1</length>
          </cylinder>
        </geometry>

        <surface>
          <friction>
            <ode>
              <mu>0.1</mu>
              <mu2>0.1</mu2>
            </ode>
          </friction>
          <contact>
            <ode>
              <soft_cfm>0.002</soft_cfm>
              <soft_erp>0.002</soft_erp>
              <kp>1000</kp>
              <kd>500</kd>
            </ode>
          </contact>
        </surface>
      </collision>

      <inertial>
        <mass>1.0</mass>
        <inertia>
          <ixx>0.01</ixx> <iyy>0.01</iyy> <izz>0.01</izz>
          <ixy>0.0</ixy> <ixz>0.0</ixz> <iyz>0.0</iyz>
        </inertia>
      </inertial>
    </link>

    <joint name="guide_L_joint" type="revolute">
      <parent>wheel_L3_link</parent>
      <child>guide_L_link</child>

      <pose>0 0 0 0 0 0</pose>

      <axis>
        <xyz>0 1 0</xyz>

        <limit>
          <lower>-1000000</lower>
          <upper>1000000</upper> 
        </limit>

        <dynamics>
          <damping>0.1</damping> 
          <friction>0.0</friction> 
        </dynamics>

      </axis>

    </joint> -->

  </model>
</sdf>